<?xml version="1.0"?>

<robot name="dofbot">

    <link name="base_link">

    </link>



    <joint name="joint1" type="revolute">

        <parent link="base_link" />

        <child link="Shoulder_Link" />

        <origin xyz="0 0 0.08" rpy="0 0 0" />

        <axis xyz="0 0 1" />

        <limit lower="-1.57" upper="1.57" effort="30" velocity="1.0" />

    </joint>



    <link name="Shoulder_Link">

    </link>



    <joint name="joint2" type="revolute">

        <parent link="Shoulder_Link" />

        <child link="Upper_Arm_Link" />

        <origin xyz="0 0 0.04" rpy="0 0 0" />

        <axis xyz="0.0 -1 0.0" />

        <limit lower="-1.57" upper="1.57" effort="30" velocity="1.0" />

    </joint>



    <link name="Upper_Arm_Link">

    </link>



    <joint name="joint3" type="revolute">

        <parent link="Upper_Arm_Link" />

        <child link="Forearm_Link" />

        <origin xyz="0 0 0.08" rpy="0 0 0" />

        <axis xyz="0.0 -1 0.0" />

        <limit lower="-1.57" upper="1.57" effort="30" velocity="1.0" />

    </joint>



    <link name="Forearm_Link">

    </link>



    <joint name="joint4" type="revolute">

        <parent link="Forearm_Link" />

        <child link="Wrist_Link" />

        <origin xyz="0 0 0.08" rpy="0 0 0" />

        <axis xyz="0.0 -1 0.0" />

        <limit lower="-1.57" upper="1.57" effort="30" velocity="1.0" />

    </joint>



    <link name="Wrist_Link">

    </link>



    <joint name="joint5" type="revolute">

        <parent link="Wrist_Link" />

        <child link="Hand" />

        <origin xyz="0 0 0.08" rpy="0 0 0" />

        <axis xyz="0.0 0.0 -1" />

        <limit lower="-1.57" upper="1.57" effort="30" velocity="1.0" />

    </joint>



    <link name="Hand">

        <collision>

            <origin xyz="0 0 0.025" />

            <geometry>

                <box size="0.02 0.02 0.05" />

            </geometry>

        </collision>

    </link>



    <joint name="gripper" type="fixed">

        <parent link="Hand" />

        <child link="end_effector_link" />

        <origin xyz="0 0 0.11" />

    </joint>



    <link name="end_effector_link"/>

</robot>
